#VRML_SIM R2021a utf8
WorldInfo {
  coordinateSystem "NUE"
}
Viewpoint {
  orientation -0.40273262991767744 0.8926876643711457 0.20227496799945333 0.9940175234786065
  position 3.2314393430123345 2.049586894335065 2.6053532928943697
}
TexturedBackground {
}
TexturedBackgroundLight {
}
RectangleArena {
  floorSize 2 2
}
Robot {
  translation 0 0.05 0
  rotation 0 -1 0 2.05009e-06
  children [
    DEF base_link Shape {
      appearance PBRAppearance {
        baseColor 0.49 0.55 0.43
        roughness 0.7
        metalness 0.8
        name "PEEK"
      }
      geometry Box {
        size 0.38 0.03 0.15
      }
    }
    HingeJoint {
      jointParameters HingeJointParameters {
        axis 0 0 -1
        anchor 0.1 0 0.1
      }
      device [
        RotationalMotor {
          name "right_front_wheel"
        }
      ]
      endPoint Solid {
        translation 0.1 0 0.1
        rotation 1 0 1.5707179855829958e-16 1.57
        children [
          DEF wheel_shape Shape {
            appearance PBRAppearance {
              baseColor 0 0 0
            }
            geometry Cylinder {
              height 0.05
              radius 0.055
            }
          }
        ]
        name "right_front_wheel"
        boundingObject USE wheel_shape
        physics DEF wheel_physics Physics {
        }
        locked TRUE
      }
    }
    HingeJoint {
      jointParameters HingeJointParameters {
        axis 0 0 -1
        anchor -0.02 0 0.1
      }
      device [
        RotationalMotor {
          name "right_mid_wheel"
        }
      ]
      endPoint Solid {
        translation -0.02 0 0.1
        rotation 1 0 0 1.57
        children [
          USE wheel_shape
        ]
        name "right_mid_wheel"
        boundingObject USE wheel_shape
        physics USE wheel_physics
        locked TRUE
      }
    }
    HingeJoint {
      jointParameters HingeJointParameters {
        axis 0 0 -1
        anchor -0.14 0 0.1
      }
      device [
        RotationalMotor {
          name "right_rear_wheel"
        }
      ]
      endPoint Solid {
        translation -0.14 0 0.1
        rotation 1 3.926794963957489e-17 1.1780384891872466e-16 1.57
        children [
          USE wheel_shape
        ]
        name "right_rear_wheel"
        boundingObject USE wheel_shape
        physics USE wheel_physics
        locked TRUE
      }
    }
    HingeJoint {
      jointParameters HingeJointParameters {
        axis 0 0 -1
        anchor 0.1 0 -0.1
      }
      device [
        RotationalMotor {
          name "left_front_wheel"
        }
      ]
      endPoint Solid {
        translation 0.1 0 -0.1
        rotation 1 0 0 1.57
        children [
          USE wheel_shape
        ]
        name "left_front_wheel"
        boundingObject USE wheel_shape
        physics USE wheel_physics
        locked TRUE
      }
    }
    HingeJoint {
      jointParameters HingeJointParameters {
        axis 0 0 -1
        anchor -0.02 0 -0.1
      }
      device [
        RotationalMotor {
          name "left_mid_wheel"
        }
      ]
      endPoint Solid {
        translation -0.02 0 -0.1
        rotation 1 0 0 1.57
        children [
          USE wheel_shape
        ]
        name "left_mid_wheel"
        boundingObject USE wheel_shape
        physics USE wheel_physics
        locked TRUE
      }
    }
    HingeJoint {
      jointParameters HingeJointParameters {
        axis 0 0 -1
        anchor -0.14 0 -0.1
      }
      device [
        RotationalMotor {
          name "left_rear_wheel"
        }
      ]
      endPoint Solid {
        translation -0.14 0 -0.1
        rotation 1 -7.853589927914978e-17 -2.356076978374493e-16 1.57
        children [
          USE wheel_shape
        ]
        name "left_rear_wheel"
        boundingObject USE wheel_shape
        physics USE wheel_physics
        locked TRUE
      }
    }
    DistanceSensor {
      translation 0.285 0 0.075
      children [
        DEF ir_shape Shape {
          appearance PBRAppearance {
            baseColor 0.49 0.55 0.43
            roughness 0.7
            metalness 0.8
            name "PEEK"
          }
          geometry Box {
            size 0.01 0.01 0.01
          }
        }
      ]
      name "right_outer_sensor"
      boundingObject USE ir_shape
      physics DEF ir_physics Physics {
      }
      locked TRUE
      lookupTable [
        0 0 0
        0.2 1000 0
      ]
    }
    DistanceSensor {
      translation 0.285 0 0.025
      children [
        DEF ir_shape Shape {
          appearance PBRAppearance {
            baseColor 0.49 0.55 0.43
            roughness 0.7
            metalness 0.8
            name "PEEK"
          }
          geometry Box {
            size 0.01 0.01 0.01
          }
        }
      ]
      name "right_mid_sensor"
      boundingObject USE ir_shape
      physics DEF ir_physics Physics {
      }
      lookupTable [
        0 0 0
        0.2 1000 0
      ]
    }
    DistanceSensor {
      translation 0.285 0 -0.075
      children [
        DEF ir_shape Shape {
          appearance PBRAppearance {
            baseColor 0.49 0.55 0.43
            roughness 0.7
            metalness 0.8
            name "PEEK"
          }
          geometry Box {
            size 0.01 0.01 0.01
          }
        }
      ]
      name "left_outer_sensor"
      boundingObject USE ir_shape
      physics DEF ir_physics Physics {
      }
      locked TRUE
      lookupTable [
        0 0 0
        0.2 1000 0
      ]
    }
    DistanceSensor {
      translation 0.285 0 -0.025
      children [
        DEF ir_shape Shape {
          appearance PBRAppearance {
            baseColor 0.49 0.55 0.43
            roughness 0.7
            metalness 0.8
            name "PEEK"
          }
          geometry Box {
            size 0.01 0.01 0.01
          }
        }
      ]
      name "left_mid_sensor"
      boundingObject USE ir_shape
      physics DEF ir_physics Physics {
      }
      lookupTable [
        0 0 0
        0.2 1000 0
      ]
    }
    DistanceSensor {
      translation 0.275 0 0.085
      rotation 0 1 0 -1.57
      children [
        Shape {
          appearance PBRAppearance {
            baseColor 0.49 0.55 0.43
            roughness 0.7
            metalness 0.8
            name "PEEK"
          }
          geometry Box {
            size 0.01 0.01 0.01
          }
        }
      ]
      name "right_side_sensor"
      boundingObject USE ir_shape
      physics USE ir_physics
      locked TRUE
      lookupTable [
        0 0 0
        0.2 1000 0
      ]
    }
    DistanceSensor {
      translation 0.275 0 -0.085
      rotation 0 1 0 1.57
      children [
        Shape {
          appearance PBRAppearance {
            baseColor 0.49 0.55 0.43
            roughness 0.7
            metalness 0.8
            name "PEEK"
          }
          geometry Box {
            size 0.01 0.01 0.01
          }
        }
      ]
      name "left_side_sensor"
      boundingObject USE ir_shape
      physics USE ir_physics
      locked TRUE
      lookupTable [
        0 0 0
        0.2 1000 0
      ]
    }
    Camera {
      translation 0.115 0.185 -0.001
      rotation 0 1 0 -1.57
      children [
        Transform {
          rotation 1 0 0 1.57
          children [
            DEF camera_shape Shape {
              appearance PBRAppearance {
                baseColor 1 0.999969 0.999985
                metalness 0
              }
              geometry Cylinder {
                height 0.015
                radius 0.008
              }
            }
          ]
        }
      ]
      name "front_camera"
      boundingObject Transform {
        rotation 1 0 0 1.57
        children [
          DEF camera_shape Shape {
            appearance PBRAppearance {
              baseColor 1 0.999969 0.999985
              metalness 0
            }
            geometry Cylinder {
              height 0.01
              radius 0.008
            }
          }
        ]
      }
      locked TRUE
    }
    Solid {
      translation 0 0.05 -0.065
      children [
        DEF basket_shape Shape {
          appearance PBRAppearance {
            baseColor 0.49 0.55 0.43
            roughness 0.7
            metalness 0.8
            name "PEEK"
          }
          geometry Box {
            size 0.37 0.1 0.01
          }
        }
      ]
      name "left basket"
      boundingObject USE basket_shape
      physics Physics {
      }
      locked TRUE
    }
    Solid {
      translation 0 0.05 0.065
      children [
        DEF basket_shape Shape {
          appearance PBRAppearance {
            baseColor 0.49 0.55 0.43
            roughness 0.7
            metalness 0.8
            name "PEEK"
          }
          geometry Box {
            size 0.37 0.1 0.01
          }
        }
      ]
      name "right basket"
      boundingObject USE basket_shape
      physics Physics {
      }
      locked TRUE
    }
    Solid {
      translation -0.18 0.05 0
      rotation 0 1 0 1.57
      children [
        DEF basket_shape Shape {
          appearance PBRAppearance {
            baseColor 0.49 0.55 0.43
            roughness 0.7
            metalness 0.8
            name "PEEK"
          }
          geometry Box {
            size 0.14 0.1 0.01
          }
        }
      ]
      name "back basket"
      boundingObject USE basket_shape
      physics Physics {
      }
      locked TRUE
    }
    Solid {
      translation 0.14 0.05 0
      rotation 0 1 0 1.57
      children [
        DEF basket_shape Shape {
          appearance PBRAppearance {
            baseColor 0.49 0.55 0.43
            roughness 0.7
            metalness 0.8
            name "PEEK"
          }
          geometry Box {
            size 0.13 0.1 0.08
          }
        }
      ]
      name "motor_box"
      boundingObject USE basket_shape
      physics Physics {
      }
      locked TRUE
    }
    Solid {
      translation 0.11 0.1 0
      rotation 0 1 0 1.57
      children [
        DEF basket_shape Shape {
          appearance PBRAppearance {
            baseColor 0.49 0.55 0.43
            roughness 0.7
            metalness 0.8
            name "PEEK"
          }
          geometry Box {
            size 0.02 0.2 0.02
          }
        }
      ]
      name "camera_bar"
      boundingObject USE basket_shape
      physics Physics {
      }
      locked TRUE
    }
    Solid {
      translation 0.18 0.04 -0.06
      rotation 1 0 0 1.57
      children [
        Shape {
          appearance PBRAppearance {
            baseColor 0.49 0.55 0.43
            roughness 0.7
            metalness 0.8
            name "PEEK"
          }
          geometry Cylinder {
            height 0.01
            radius 0.08
          }
        }
      ]
      name "pine coil"
      boundingObject Shape {
        appearance PBRAppearance {
          roughness 1
          metalness 0
        }
        geometry Cylinder {
          height 0.01
          radius 0.08
        }
      }
      physics Physics {
      }
      locked TRUE
    }
    Solid {
      translation 0.18 0.04 0
      rotation 1 0 0 1.57
      children [
        Shape {
          appearance PBRAppearance {
            baseColor 0.49 0.55 0.43
            roughness 0.7
            metalness 0.8
            name "PEEK"
          }
          geometry Cylinder {
            height 0.01
            radius 0.08
          }
        }
      ]
      name "pine coil(4)"
      boundingObject Shape {
        appearance PBRAppearance {
          roughness 1
          metalness 0
        }
        geometry Cylinder {
          height 0.01
          radius 0.08
        }
      }
      physics Physics {
      }
      locked TRUE
    }
    Solid {
      translation 0.18 0.04 0.03
      rotation 1 0 0 1.57
      children [
        Shape {
          appearance PBRAppearance {
            baseColor 0.49 0.55 0.43
            roughness 0.7
            metalness 0.8
            name "PEEK"
          }
          geometry Cylinder {
            height 0.01
            radius 0.08
          }
        }
      ]
      name "pine coil(1)"
      boundingObject Shape {
        appearance PBRAppearance {
          roughness 1
          metalness 0
        }
        geometry Cylinder {
          height 0.01
          radius 0.08
        }
      }
      physics Physics {
      }
      locked TRUE
    }
    Solid {
      translation 0.18 0.04 -0.03
      rotation 1 0 0 1.57
      children [
        Shape {
          appearance PBRAppearance {
            baseColor 0.49 0.55 0.43
            roughness 0.7
            metalness 0.8
            name "PEEK"
          }
          geometry Cylinder {
            height 0.01
            radius 0.08
          }
        }
      ]
      name "pine coil(2)"
      boundingObject Shape {
        appearance PBRAppearance {
          roughness 1
          metalness 0
        }
        geometry Cylinder {
          height 0.01
          radius 0.08
        }
      }
      physics Physics {
      }
      locked TRUE
    }
    Solid {
      translation 0.18 0.04 0.06
      rotation 1 0 0 1.57
      children [
        Shape {
          appearance PBRAppearance {
            baseColor 0.49 0.55 0.43
            roughness 0.7
            metalness 0.8
            name "PEEK"
          }
          geometry Cylinder {
            height 0.01
            radius 0.08
          }
        }
      ]
      name "pine coil(3)"
      boundingObject Shape {
        appearance PBRAppearance {
          roughness 1
          metalness 0
        }
        geometry Cylinder {
          height 0.01
          radius 0.08
        }
      }
      physics Physics {
      }
      locked TRUE
    }
    Solid {
      translation 0.225 0 -0.08
      rotation 0.577656895078166 0.5771968951617173 -0.5771968951617173 2.09394
      children [
        DEF basket_shape Shape {
          appearance PBRAppearance {
            baseColor 0.49 0.55 0.43
            roughness 0.7
            metalness 0.8
            name "PEEK"
          }
          geometry Box {
            size 0.01 0.12 0.015
          }
        }
      ]
      name "left sensor bar"
      boundingObject USE basket_shape
      physics Physics {
      }
      locked TRUE
    }
    Solid {
      translation 0.225 0 0.08
      rotation 0.577656895078166 0.5771968951617173 -0.5771968951617173 2.09394
      children [
        DEF basket_shape Shape {
          appearance PBRAppearance {
            baseColor 0.49 0.55 0.43
            roughness 0.7
            metalness 0.8
            name "PEEK"
          }
          geometry Box {
            size 0.01 0.12 0.015
          }
        }
      ]
      name "right sensor bar"
      boundingObject USE basket_shape
      physics Physics {
      }
      locked TRUE
    }
    Solid {
      translation 0.28 0 0
      rotation 1 0 0 1.5708
      children [
        DEF basket_shape Shape {
          appearance PBRAppearance {
            baseColor 0.49 0.55 0.43
            roughness 0.7
            metalness 0.8
            name "PEEK"
          }
          geometry Box {
            size 0.01 0.17 0.015
          }
        }
      ]
      name "front sensor bar"
      boundingObject USE basket_shape
      physics Physics {
      }
      locked TRUE
    }
  ]
  name "GardenRobot"
  boundingObject USE base_link
  physics Physics {
  }
  controller "robot_controller_six"
}
