#VRML_SIM R2021a utf8
WorldInfo {
  coordinateSystem "NUE"
}
Viewpoint {
  orientation -0.0008657269065851993 -0.9375356063383918 -0.3478882541343231 3.154432741430381
  position -0.00610151730975997 2.9327801226024506 -3.3503314904563313
}
TexturedBackground {
}
TexturedBackgroundLight {
}
RectangleArena {
  floorSize 2 2
}
Robot {
  translation -0.080817 0.05 -0.0182777
  rotation 0 -1 0 6.53317e-06
  children [
    DEF base_link Shape {
      appearance PBRAppearance {
        baseColor 0.0659342 0.501793 0.00683604
        metalness 0
      }
      geometry Box {
        size 0.38 0.03 0.15
      }
    }
    HingeJoint {
      jointParameters HingeJointParameters {
        axis 0 0 -1
        anchor 0.1 0 0.08
      }
      device [
        RotationalMotor {
          name "right_front_wheel"
        }
      ]
      endPoint Solid {
        translation 0.1 0 0.08
        rotation 1 0 1.5707179855829958e-16 1.57
        children [
          DEF wheel_shape Shape {
            appearance PBRAppearance {
              baseColor 0.8 0.5 0
              metalness 0
            }
            geometry Cylinder {
              height 0.01
              radius 0.055
            }
          }
        ]
        name "right_front_wheel"
        boundingObject USE wheel_shape
        physics DEF wheel_physics Physics {
        }
        locked TRUE
      }
    }
    HingeJoint {
      jointParameters HingeJointParameters {
        axis 0 0 -1
        anchor -0.02 0 0.08
      }
      device [
        RotationalMotor {
          name "right_mid_wheel"
        }
      ]
      endPoint Solid {
        translation -0.02 0 0.08
        rotation 1 0 0 1.57
        children [
          USE wheel_shape
        ]
        name "right_mid_wheel"
        boundingObject USE wheel_shape
        physics USE wheel_physics
        locked TRUE
      }
    }
    HingeJoint {
      jointParameters HingeJointParameters {
        axis 0 0 -1
        anchor -0.14 0 0.08
      }
      device [
        RotationalMotor {
          name "right_rear_wheel"
        }
      ]
      endPoint Solid {
        translation -0.14 0 0.08
        rotation 1 3.926794963957489e-17 1.1780384891872466e-16 1.57
        children [
          USE wheel_shape
        ]
        name "right_rear_wheel"
        boundingObject USE wheel_shape
        physics USE wheel_physics
        locked TRUE
      }
    }
    HingeJoint {
      jointParameters HingeJointParameters {
        axis 0 0 -1
        anchor 0.1 0 -0.08
      }
      device [
        RotationalMotor {
          name "left_front_wheel"
        }
      ]
      endPoint Solid {
        translation 0.09999999999999999 0 -0.08
        rotation 1 0 0 1.57
        children [
          USE wheel_shape
        ]
        name "left_front_wheel"
        boundingObject USE wheel_shape
        physics USE wheel_physics
        locked TRUE
      }
    }
    HingeJoint {
      jointParameters HingeJointParameters {
        axis 0 0 -1
        anchor -0.02 0 -0.08
      }
      device [
        RotationalMotor {
          name "left_mid_wheel"
        }
      ]
      endPoint Solid {
        translation -0.02 0 -0.08
        rotation 1 0 0 1.57
        children [
          USE wheel_shape
        ]
        name "left_mid_wheel"
        boundingObject USE wheel_shape
        physics USE wheel_physics
        locked TRUE
      }
    }
    HingeJoint {
      jointParameters HingeJointParameters {
        axis 0 0 -1
        anchor -0.14 0 -0.08
      }
      device [
        RotationalMotor {
          name "left_rear_wheel"
        }
      ]
      endPoint Solid {
        translation -0.14 0 -0.08
        rotation 1 -7.853589927914978e-17 -2.356076978374493e-16 1.57
        children [
          USE wheel_shape
        ]
        name "left_rear_wheel"
        boundingObject USE wheel_shape
        physics USE wheel_physics
        locked TRUE
      }
    }
    DistanceSensor {
      translation 0.19 -0.0075 0.075
      children [
        DEF ir_shape Shape {
          appearance PBRAppearance {
            baseColor 0 1 1
            metalness 0
          }
          geometry Box {
            size 0.01 0.01 0.01
          }
        }
      ]
      name "right_outer_sensor"
      boundingObject USE ir_shape
      physics DEF ir_physics Physics {
      }
      locked TRUE
      lookupTable [
        0 0 0
        0.15 1000 0
      ]
    }
    DistanceSensor {
      translation 0.19 -0.0075 0.025
      children [
        DEF ir_shape Shape {
          appearance PBRAppearance {
            baseColor 0 1 1
            metalness 0
          }
          geometry Box {
            size 0.01 0.01 0.01
          }
        }
      ]
      name "right_mid_sensor"
      boundingObject USE ir_shape
      physics DEF ir_physics Physics {
      }
      locked TRUE
      lookupTable [
        0 0 0
        0.15 1000 0
      ]
    }
    DistanceSensor {
      translation 0.19 -0.0075 -0.075
      children [
        DEF ir_shape Shape {
          appearance PBRAppearance {
            baseColor 0 1 1
            metalness 0
          }
          geometry Box {
            size 0.01 0.01 0.01
          }
        }
      ]
      name "left_outer_sensor"
      boundingObject USE ir_shape
      physics DEF ir_physics Physics {
      }
      locked TRUE
      lookupTable [
        0 0 0
        0.15 1000 0
      ]
    }
    DistanceSensor {
      translation 0.19 -0.0075 -0.025
      children [
        DEF ir_shape Shape {
          appearance PBRAppearance {
            baseColor 0 1 1
            metalness 0
          }
          geometry Box {
            size 0.01 0.01 0.01
          }
        }
      ]
      name "left_mid_sensor"
      boundingObject USE ir_shape
      physics DEF ir_physics Physics {
      }
      locked TRUE
      lookupTable [
        0 0 0
        0.15 1000 0
      ]
    }
    DistanceSensor {
      translation 0.17 -0.0075 0.0749601
      rotation 0 1 0 -1.57
      children [
        Shape {
          appearance PBRAppearance {
            baseColor 0 1 1
            metalness 0
          }
          geometry Box {
            size 0.01 0.01 0.01
          }
        }
      ]
      name "right_side_sensor"
      boundingObject USE ir_shape
      physics USE ir_physics
      locked TRUE
      lookupTable [
        0 0 0
        0.15 1000 0
      ]
    }
    DistanceSensor {
      translation 0.17 -0.0075 -0.0749601
      rotation 0 1 0 1.57
      children [
        Shape {
          appearance PBRAppearance {
            baseColor 0 1 1
            metalness 0
          }
          geometry Box {
            size 0.01 0.01 0.01
          }
        }
      ]
      name "left_side_sensor"
      boundingObject USE ir_shape
      physics USE ir_physics
      locked TRUE
      lookupTable [
        0 0 0
        0.15 1000 0
      ]
    }
    Camera {
      translation 0.13 0.18 -1.16711e-09
      rotation 0 1 0 -1.57
      children [
        DEF camera_shape Shape {
          appearance PBRAppearance {
            baseColor 1 0.999969 0.999985
            metalness 0
          }
          geometry Cylinder {
            height 0.01
            radius 0.01
          }
        }
      ]
      name "front_camera"
      boundingObject USE camera_shape
      physics Physics {
      }
      locked TRUE
    }
    Solid {
      translation 0 0.05 -0.065
      children [
        DEF basket_shape Shape {
          appearance PBRAppearance {
            baseColor 0 1 0
            metalness 0
          }
          geometry Box {
            size 0.37 0.1 0.01
          }
        }
      ]
      name "left basket"
      boundingObject USE basket_shape
      physics Physics {
      }
      locked TRUE
    }
    Solid {
      translation 0 0.05 0.065
      children [
        DEF basket_shape Shape {
          appearance PBRAppearance {
            baseColor 0 1 0
            metalness 0
          }
          geometry Box {
            size 0.37 0.1 0.01
          }
        }
      ]
      name "right basket"
      boundingObject USE basket_shape
      physics Physics {
      }
      locked TRUE
    }
    Solid {
      translation -0.18 0.05 0
      rotation 0 1 0 1.57
      children [
        DEF basket_shape Shape {
          appearance PBRAppearance {
            baseColor 0 1 0
            metalness 0
          }
          geometry Box {
            size 0.14 0.1 0.01
          }
        }
      ]
      name "back basket"
      boundingObject USE basket_shape
      physics Physics {
      }
      locked TRUE
    }
    Solid {
      translation 0.18 0.05 0
      rotation 0 1 0 1.57
      children [
        DEF basket_shape Shape {
          appearance PBRAppearance {
            baseColor 0 1 0
            metalness 0
          }
          geometry Box {
            size 0.14 0.1 0.01
          }
        }
      ]
      name "front basket"
      boundingObject USE basket_shape
      physics Physics {
      }
      locked TRUE
    }
    Solid {
      translation 0.15 0.05 0
      rotation 0 1 0 1.57
      children [
        DEF basket_shape Shape {
          appearance PBRAppearance {
            baseColor 0 1 0
            metalness 0
          }
          geometry Box {
            size 0.14 0.1 0.05
          }
        }
      ]
      name "motor_box"
      boundingObject USE basket_shape
      physics Physics {
      }
      locked TRUE
    }
    Solid {
      translation 0.125 0.1 0
      rotation 0 1 0 1.57
      children [
        DEF basket_shape Shape {
          appearance PBRAppearance {
            baseColor 0 1 0
            metalness 0
          }
          geometry Box {
            size 0.02 0.2 0.02
          }
        }
      ]
      name "camera_bar"
      boundingObject USE basket_shape
      physics Physics {
      }
      locked TRUE
    }
  ]
  name "GardenRobot"
  boundingObject USE base_link
  physics Physics {
  }
  controller "<extern>"
}
